export const asyncErrorhanlder=thefunc=>(req,res,next)=>{
         Promise.resolve(thefunc(req,res,next)).catch(next)}